======================================================================
FAIL: test_add_two_zero (PythonStudy.unit_test.unit_test.TestMathMethod)
----------------------------------------------------------------------
Traceback (most recent call last):
  File "/Users/szdl/Desktop/PythonStudy/PythonStudy/unit_test/unit_test.py", line 51, in test_add_two_zero
    raise e
  File "/Users/szdl/Desktop/PythonStudy/PythonStudy/unit_test/unit_test.py", line 48, in test_add_two_zero
    self.assertEqual(1, res, "两个0相加出错了")
AssertionError: 1 != 0 : 两个0相加出错了

----------------------------------------------------------------------
Ran 6 tests in 0.001s

FAILED (failures=1)
